Workbook

Sheet Caudal de Diseño
B1: A-B
B2: CALCULO DE CAUDAL DE DISEÑO DE AGUA POTABLE FRÍA Y CALIENTE
B3: Predominan | C3: Tanques
B4: Tipo de uso | C4: Privado
B6: Pieza | C6: Cantidad de piezas | D6: Unidades accesorio por pieza | E6: Tipo de agua | F6: Unidades accesorio Total | G6: Unidades accesorio por pieza | H6: Unidades accesorio Agua Fría Total | I6: Unidades accesorio por pieza | J6: Unidades accesorio Agua Caliente Total
B7: Inodoro con tanque | C7: 5 | D7: =IF(IF($C$4="Privado",1,0)=1,VLOOKUP(B7,'Piezas Sanitarias'!$B$4:$F$20,4,FALSE),VLOOKUP(B7,'Piezas Sanitarias'!$B$4:$F$20,5,FALSE)) -> 3 | E7: Fría | F7: =C7*D7 -> 15 | G7: =IF(E7="Fría",D7,D7*3/4) -> 3 | H7: =C7*G7 -> 15 | I7: =IF(E7="Fría",0,D7*3/4) -> 0 | J7: =C7*I7 -> 0
B8: Lavatorio | C8: 5 | D8: =IF(IF($C$4="Privado",1,0)=1,VLOOKUP(B8,'Piezas Sanitarias'!$B$4:$F$20,4,FALSE),VLOOKUP(B8,'Piezas Sanitarias'!$B$4:$F$20,5,FALSE)) -> 1 | E8: Fría y Caliente | F8: =C8*D8 -> 5 | G8: =IF(E8="Fría",D8,D8*3/4) -> 0.75 | H8: =C8*G8 -> 3.75 | I8: =IF(E8="Fría",0,D8*3/4) -> 0.75 | J8: =C8*I8 -> 3.75
B9: Ducha | C9: 2 | D9: =IF(IF($C$4="Privado",1,0)=1,VLOOKUP(B9,'Piezas Sanitarias'!$B$4:$F$20,4,FALSE),VLOOKUP(B9,'Piezas Sanitarias'!$B$4:$F$20,5,FALSE)) -> 2 | E9: Fría y Caliente | F9: =C9*D9 -> 4 | G9: =IF(E9="Fría",D9,D9*3/4) -> 1.5 | H9: =C9*G9 -> 3 | I9: =IF(E9="Fría",0,D9*3/4) -> 1.5 | J9: =C9*I9 -> 3
B10: Pileta de lavar | C10: 1 | D10: =IF(IF($C$4="Privado",1,0)=1,VLOOKUP(B10,'Piezas Sanitarias'!$B$4:$F$20,4,FALSE),VLOOKUP(B10,'Piezas Sanitarias'!$B$4:$F$20,5,FALSE)) -> 2 | E10: Fría | F10: =C10*D10 -> 2 | G10: =IF(E10="Fría",D10,D10*3/4) -> 2 | H10: =C10*G10 -> 2 | I10: =IF(E10="Fría",0,D10*3/4) -> 0 | J10: =C10*I10 -> 0
B11: Fregadero doméstico | C11: 2 | D11: =IF(IF($C$4="Privado",1,0)=1,VLOOKUP(B11,'Piezas Sanitarias'!$B$4:$F$20,4,FALSE),VLOOKUP(B11,'Piezas Sanitarias'!$B$4:$F$20,5,FALSE)) -> 2 | E11: Fría y Caliente | F11: =C11*D11 -> 4 | G11: =IF(E11="Fría",D11,D11*3/4) -> 1.5 | H11: =C11*G11 -> 3 | I11: =IF(E11="Fría",0,D11*3/4) -> 1.5 | J11: =C11*I11 -> 3
D12: =IF(IF($C$4="Privado",1,0)=1,VLOOKUP(B12,'Piezas Sanitarias'!$B$4:$F$20,4,FALSE),VLOOKUP(B12,'Piezas Sanitarias'!$B$4:$F$20,5,FALSE)) -> 0 | E12: Fría y Caliente | F12: =C12*D12 -> 0 | G12: =IF(E12="Fría",D12,D12*3/4) -> 0 | H12: =C12*G12 -> 0 | I12: =IF(E12="Fría",0,D12*3/4) -> 0 | J12: =C12*I12 -> 0
D13: =IF(IF($C$4="Privado",1,0)=1,VLOOKUP(B13,'Piezas Sanitarias'!$B$4:$F$20,4,FALSE),VLOOKUP(B13,'Piezas Sanitarias'!$B$4:$F$20,5,FALSE)) -> 0 | E13: Fría y Caliente | F13: =C13*D13 -> 0 | G13: =IF(E13="Fría",D13,D13*3/4) -> 0 | H13: =C13*G13 -> 0 | I13: =IF(E13="Fría",0,D13*3/4) -> 0 | J13: =C13*I13 -> 0
D14: =IF(IF($C$4="Privado",1,0)=1,VLOOKUP(B14,'Piezas Sanitarias'!$B$4:$F$20,4,FALSE),VLOOKUP(B14,'Piezas Sanitarias'!$B$4:$F$20,5,FALSE)) -> 0 | E14: Fría | F14: =C14*D14 -> 0 | G14: =IF(E14="Fría",D14,D14*3/4) -> 0 | H14: =C14*G14 -> 0 | I14: =IF(E14="Fría",0,D14*3/4) -> 0 | J14: =C14*I14 -> 0
D15: =IF(IF($C$4="Privado",1,0)=1,VLOOKUP(B15,'Piezas Sanitarias'!$B$4:$F$20,4,FALSE),VLOOKUP(B15,'Piezas Sanitarias'!$B$4:$F$20,5,FALSE)) -> 0 | E15: Fría | F15: =C15*D15 -> 0 | G15: =IF(E15="Fría",D15,D15*3/4) -> 0 | H15: =C15*G15 -> 0 | I15: =IF(E15="Fría",0,D15*3/4) -> 0 | J15: =C15*I15 -> 0
D16: =IF(IF($C$4="Privado",1,0)=1,VLOOKUP(B16,'Piezas Sanitarias'!$B$4:$F$20,4,FALSE),VLOOKUP(B16,'Piezas Sanitarias'!$B$4:$F$20,5,FALSE)) -> 0 | E16: Fría | F16: =C16*D16 -> 0 | G16: =IF(E16="Fría",D16,D16*3/4) -> 0 | H16: =C16*G16 -> 0 | I16: =IF(E16="Fría",0,D16*3/4) -> 0 | J16: =C16*I16 -> 0
D17: TOTAL | F17: =SUM(F7:F16) -> 30 | H17: =SUM(H7:H16) -> 26.75 | J17: =SUM(J7:J16) -> 9.75
D18: Caudal probable | F18: =(IFERROR( IF($C$3="Tanques", IF(F17<100, 0.13*POWER(F17,0.669), 0.0145*F17+1.39-0.00000283*POWER(F17,2) ), IF($C$3="Fluxometros", IF(F17<150, 0.68*POWER(F17,0.4), 0.0122*F17+3.37-0.00000215*POWER(F17,2) ) ) ), 0))/1000 -> 0.0012651368 | G18: m3/s | H18: =(IFERROR( IF($C$3="Tanques", IF(H17<100, 0.13*POWER(H17,0.669), 0.0145*H17+1.39-0.00000283*POWER(H17,2) ), IF($C$3="Fluxometros", IF(H17<150, 0.68*POWER(H17,0.4), 0.0122*H17+3.37-0.00000215*POWER(H17,2) ) ) ), 0))/1000 -> 0.0011717176 | I18: m3/s | J18: =(IFERROR( IF($C$3="Tanques", IF(J17<100, 0.13*POWER(J17,0.669), 0.0145*J17+1.39-0.00000283*POWER(J17,2) ), IF($C$3="Fluxometros", IF(J17<150, 0.68*POWER(J17,0.4), 0.0122*J17+3.37-0.00000215*POWER(J17,2) ) ) ), 0))/1000 -> 0.0005964684 | K18: m3/s
F19: =(IFERROR( IF($C$3="Tanques", IF(F17<100, 0.13*POWER(F17,0.669), 0.0145*F17+1.39-0.00000283*POWER(F17,2) ), IF($C$3="Fluxometros", IF(F17<150, 0.68*POWER(F17,0.4), 0.0122*F17+3.37-0.00000215*POWER(F17,2) ) ) ), 0)) -> 1.2651368 | G19: l/s | H19: =(IFERROR( IF($C$3="Tanques", IF(H17<100, 0.13*POWER(H17,0.669), 0.0145*H17+1.39-0.00000283*POWER(H17,2) ), IF($C$3="Fluxometros", IF(H17<150, 0.68*POWER(H17,0.4), 0.0122*H17+3.37-0.00000215*POWER(H17,2) ) ) ), 0)) -> 1.1717176 | I19: l/s | J19: =(IFERROR( IF($C$3="Tanques", IF(J17<100, 0.13*POWER(J17,0.669), 0.0145*J17+1.39-0.00000283*POWER(J17,2) ), IF($C$3="Fluxometros", IF(J17<150, 0.68*POWER(J17,0.4), 0.0122*J17+3.37-0.00000215*POWER(J17,2) ) ) ), 0)) -> 0.5964684 | K19: l/s
B23: B-C
B25: CALCULO DE CAUDAL DE DISEÑO DE AGUA POTABLE FRÍA Y CALIENTE
B26: Predominan | C26: Tanques
B27: Tipo de uso | C27: Privado
B29: Pieza | C29: Cantidad de piezas | D29: Unidades accesorio por pieza | E29: Tipo de agua | F29: Unidades accesorio Total | G29: Unidades accesorio por pieza | H29: Unidades accesorio Agua Fría Total | I29: Unidades accesorio por pieza | J29: Unidades accesorio Agua Caliente Total
B30: Inodoro con tanque | C30: 2 | D30: =IF(IF($C$4="Privado",1,0)=1,VLOOKUP(B30,'Piezas Sanitarias'!$B$4:$F$20,4,FALSE),VLOOKUP(B30,'Piezas Sanitarias'!$B$4:$F$20,5,FALSE)) -> 3 | E30: Fría | F30: =C30*D30 -> 6 | G30: =IF(E30="Fría",D30,D30*3/4) -> 3 | H30: =C30*G30 -> 6 | I30: =IF(E30="Fría",0,D30*3/4) -> 0 | J30: =C30*I30 -> 0
B31: Lavatorio | C31: 2 | D31: =IF(IF($C$4="Privado",1,0)=1,VLOOKUP(B31,'Piezas Sanitarias'!$B$4:$F$20,4,FALSE),VLOOKUP(B31,'Piezas Sanitarias'!$B$4:$F$20,5,FALSE)) -> 1 | E31: Fría y Caliente | F31: =C31*D31 -> 2 | G31: =IF(E31="Fría",D31,D31*3/4) -> 0.75 | H31: =C31*G31 -> 1.5 | I31: =IF(E31="Fría",0,D31*3/4) -> 0.75 | J31: =C31*I31 -> 1.5
B32: Ducha | C32: 1 | D32: =IF(IF($C$4="Privado",1,0)=1,VLOOKUP(B32,'Piezas Sanitarias'!$B$4:$F$20,4,FALSE),VLOOKUP(B32,'Piezas Sanitarias'!$B$4:$F$20,5,FALSE)) -> 2 | E32: Fría y Caliente | F32: =C32*D32 -> 2 | G32: =IF(E32="Fría",D32,D32*3/4) -> 1.5 | H32: =C32*G32 -> 1.5 | I32: =IF(E32="Fría",0,D32*3/4) -> 1.5 | J32: =C32*I32 -> 1.5
B33: Pileta de lavar | C33: 1 | D33: =IF(IF($C$4="Privado",1,0)=1,VLOOKUP(B33,'Piezas Sanitarias'!$B$4:$F$20,4,FALSE),VLOOKUP(B33,'Piezas Sanitarias'!$B$4:$F$20,5,FALSE)) -> 2 | E33: Fría | F33: =C33*D33 -> 2 | G33: =IF(E33="Fría",D33,D33*3/4) -> 2 | H33: =C33*G33 -> 2 | I33: =IF(E33="Fría",0,D33*3/4) -> 0 | J33: =C33*I33 -> 0
B34: Fregadero doméstico | C34: 2 | D34: =IF(IF($C$4="Privado",1,0)=1,VLOOKUP(B34,'Piezas Sanitarias'!$B$4:$F$20,4,FALSE),VLOOKUP(B34,'Piezas Sanitarias'!$B$4:$F$20,5,FALSE)) -> 2 | E34: Fría y Caliente | F34: =C34*D34 -> 4 | G34: =IF(E34="Fría",D34,D34*3/4) -> 1.5 | H34: =C34*G34 -> 3 | I34: =IF(E34="Fría",0,D34*3/4) -> 1.5 | J34: =C34*I34 -> 3
D35: =IF(IF($C$4="Privado",1,0)=1,VLOOKUP(B35,'Piezas Sanitarias'!$B$4:$F$20,4,FALSE),VLOOKUP(B35,'Piezas Sanitarias'!$B$4:$F$20,5,FALSE)) -> 0 | E35: Fría y Caliente | F35: =C35*D35 -> 0 | G35: =IF(E35="Fría",D35,D35*3/4) -> 0 | H35: =C35*G35 -> 0 | I35: =IF(E35="Fría",0,D35*3/4) -> 0 | J35: =C35*I35 -> 0
D36: =IF(IF($C$4="Privado",1,0)=1,VLOOKUP(B36,'Piezas Sanitarias'!$B$4:$F$20,4,FALSE),VLOOKUP(B36,'Piezas Sanitarias'!$B$4:$F$20,5,FALSE)) -> 0 | E36: Fría y Caliente | F36: =C36*D36 -> 0 | G36: =IF(E36="Fría",D36,D36*3/4) -> 0 | H36: =C36*G36 -> 0 | I36: =IF(E36="Fría",0,D36*3/4) -> 0 | J36: =C36*I36 -> 0
D37: =IF(IF($C$4="Privado",1,0)=1,VLOOKUP(B37,'Piezas Sanitarias'!$B$4:$F$20,4,FALSE),VLOOKUP(B37,'Piezas Sanitarias'!$B$4:$F$20,5,FALSE)) -> 0 | E37: Fría | F37: =C37*D37 -> 0 | G37: =IF(E37="Fría",D37,D37*3/4) -> 0 | H37: =C37*G37 -> 0 | I37: =IF(E37="Fría",0,D37*3/4) -> 0 | J37: =C37*I37 -> 0
D38: =IF(IF($C$4="Privado",1,0)=1,VLOOKUP(B38,'Piezas Sanitarias'!$B$4:$F$20,4,FALSE),VLOOKUP(B38,'Piezas Sanitarias'!$B$4:$F$20,5,FALSE)) -> 0 | E38: Fría | F38: =C38*D38 -> 0 | G38: =IF(E38="Fría",D38,D38*3/4) -> 0 | H38: =C38*G38 -> 0 | I38: =IF(E38="Fría",0,D38*3/4) -> 0 | J38: =C38*I38 -> 0
D39: =IF(IF($C$4="Privado",1,0)=1,VLOOKUP(B39,'Piezas Sanitarias'!$B$4:$F$20,4,FALSE),VLOOKUP(B39,'Piezas Sanitarias'!$B$4:$F$20,5,FALSE)) -> 0 | E39: Fría | F39: =C39*D39 -> 0 | G39: =IF(E39="Fría",D39,D39*3/4) -> 0 | H39: =C39*G39 -> 0 | I39: =IF(E39="Fría",0,D39*3/4) -> 0 | J39: =C39*I39 -> 0
D40: TOTAL | F40: =SUM(F30:F39) -> 16 | H40: =SUM(H30:H39) -> 14 | J40: =SUM(J30:J39) -> 6
D41: Caudal probable | F41: =(IFERROR( IF($C$3="Tanques", IF(F40<100, 0.13*POWER(F40,0.669), 0.0145*F40+1.39-0.00000283*POWER(F40,2) ), IF($C$3="Fluxometros", IF(F40<150, 0.68*POWER(F40,0.4), 0.0122*F40+3.37-0.00000215*POWER(F40,2) ) ) ), 0))/1000 -> 0.00083080599 | G41: m3/s | H41: =(IFERROR( IF($C$3="Tanques", IF(H40<100, 0.13*POWER(H40,0.669), 0.0145*H40+1.39-0.00000283*POWER(H40,2) ), IF($C$3="Fluxometros", IF(H40<150, 0.68*POWER(H40,0.4), 0.0122*H40+3.37-0.00000215*POWER(H40,2) ) ) ), 0))/1000 -> 0.00075980651 | I41: m3/s | J41: =(IFERROR( IF($C$3="Tanques", IF(J40<100, 0.13*POWER(J40,0.669), 0.0145*J40+1.39-0.00000283*POWER(J40,2) ), IF($C$3="Fluxometros", IF(J40<150, 0.68*POWER(J40,0.4), 0.0122*J40+3.37-0.00000215*POWER(J40,2) ) ) ), 0))/1000 -> 0.0004310489 | K41: m3/s
F42: =(IFERROR( IF($C$3="Tanques", IF(F40<100, 0.13*POWER(F40,0.669), 0.0145*F40+1.39-0.00000283*POWER(F40,2) ), IF($C$3="Fluxometros", IF(F40<150, 0.68*POWER(F40,0.4), 0.0122*F40+3.37-0.00000215*POWER(F40,2) ) ) ), 0)) -> 0.83080599 | G42: l/s | H42: =(IFERROR( IF($C$3="Tanques", IF(H40<100, 0.13*POWER(H40,0.669), 0.0145*H40+1.39-0.00000283*POWER(H40,2) ), IF($C$3="Fluxometros", IF(H40<150, 0.68*POWER(H40,0.4), 0.0122*H40+3.37-0.00000215*POWER(H40,2) ) ) ), 0)) -> 0.75980651 | I42: l/s | J42: =(IFERROR( IF($C$3="Tanques", IF(J40<100, 0.13*POWER(J40,0.669), 0.0145*J40+1.39-0.00000283*POWER(J40,2) ), IF($C$3="Fluxometros", IF(J40<150, 0.68*POWER(J40,0.4), 0.0122*J40+3.37-0.00000215*POWER(J40,2) ) ) ), 0)) -> 0.4310489 | K42: l/s
B47: D-E
B49: CALCULO DE CAUDAL DE DISEÑO DE AGUA POTABLE FRÍA Y CALIENTE
B50: Predominan | C50: Tanques
B51: Tipo de uso | C51: Privado
...

Sheet Piezas Sanitarias
B3: Accesorio | C3: Diámetro mínimo (mm) | D3: Presión mínima (mca) | E3: Unidades de accesorio (Uso privado) | F3: Unidades de accesorio (Uso público)
B4: Tina de baño | C4: 12 | D4: 2 | E4: 2 | F4: 4
B5: Bidé | C5: 12 | D5: 3 | E5: 1 | F5: 2
B6: Ducha | C6: 12 | D6: 2 | E6: 2 | F6: 4
B7: Fregadero doméstico | C7: 12 | D7: 2 | E7: 2 | F7: 4
B8: Fregadero comercial | C8: 12 | D8: 2 | E8: 0 | F8: 4
B9: Fregadero clínicas | C9: 12 | D9: 4 | E9: 0 | F9: 8
B10: Inodoro con tanque | C10: 12 | D10: 2 | E10: 3 | F10: 5
B11: Inodoro con fluxómetro | C11: 32 | D11: 7 a 14 | E11: 6 | F11: 10
B12: Fuente para beber | C12: 12 | D12: 2,5 | E12: 0 | F12: 1
B13: Lavatorio | C13: 12 | D13: 2 | E13: 1 | F13: 2
B14: Lavadora | C14: 12 | D14: 3,5 | E14: 4 | F14: 0
B15: Llave para riego (jardín) | C15: 12 | D15: 10 | E15: 2 | F15: 2
B16: Mingitorios con tanque | C16: 18 | D16: 2 | E16: 0 | F16: 3
B17: Mingitorios con fluxómetro | C17: 18 | D17: 5 a 10 | E17: 5 | F17: 6
B18: Lavaplatos doméstico | C18: 12 | D18: 2 | E18: 1.5 | F18: 0
B19: Pileta de lavar | C19: 12 | D19: 2 | E19: 2 | F19: 4

Sheet Memoria de Cálculo (2)
B3: TRAMO | C3: Longitud | D3: Caudal | E3: Velocidad | F3: Diam | G3: Diam | H3: Diam | I3: SDR | J3: C | K3: Caída | L3: Presión | M3: Altura | N3: Tramos | O3: Ruta | P3: TRAMO
C4: tubería | F4: inter | G4: selec | H4: nominal | K4: Presión | L4: mínima | M4: geométrica | N4: Críticos | O4: Crítica
C5: (m) | D5: (m3/s) | E5: (m/s) | F5: (mm) | G5: (mm) | H5: (pulg) | K5: (mca) | L5: (mca) | M5: (m) | O5: (mca)
B7: A-B | C7: 1.75 | D7: ='Caudal de Diseño'!J18 -> 0.0005964684 | E7: 1.5 | F7: =((((4*D7)/(PI()*E7))^(0.5))*1000) -> 22.501069 | G7: 25 | I7: 26 | J7: 160 | K7: =((10.675*((D7/J7))^(1.85))*C7)/(G7/1000)^(4.87) -> 0.10731314 | P7: A-B
B8: B-C | C8: 3.1 | D8: ='Caudal de Diseño'!J274 -> 0.00027110497 | E8: 1.5 | F8: =((((4*D8)/(PI()*E8))^(0.5))*1000) -> 15.169741 | G8: 18 | I8: 26 | J8: 160 | K8: =((10.675*((D8/J8))^(1.85))*C8)/(G8/1000)^(4.87) -> 0.21889449 | P8: B-C
B9: B-D | C9: 4.98 | D9: ='Caudal de Diseño'!J297 -> 0.00046638822 | E9: 1.5 | F9: =((((4*D9)/(PI()*E9))^(0.5))*1000) -> 19.896799 | G9: 25 | I9: 26 | J9: 160 | K9: =((10.675*((D9/J9))^(1.85))*C9)/(G9/1000)^(4.87) -> 0.19372712 | P9: C-D
B10: D-E | C10: 21.38 | D10: =D9 -> 0.00046638822 | E10: 1.5 | F10: =((((4*D10)/(PI()*E10))^(0.5))*1000) -> 19.896799 | G10: 25 | I10: 26 | J10: 160 | K10: =((10.675*((D10/J10))^(1.85))*C10)/(G10/1000)^(4.87) -> 0.831704 | P10: D-E
B11: E-F | C11: 7.1 | D11: =D10 -> 0.00046638822 | E11: 1.5 | F11: =((((4*D11)/(PI()*E11))^(0.5))*1000) -> 19.896799 | G11: 25 | I11: 26 | J11: 160 | K11: =((10.675*((D11/J11))^(1.85))*C11)/(G11/1000)^(4.87) -> 0.27619731 | P11: E-F
B12: F-G | C12: 2.83 | D12: ='Caudal de Diseño'!J320 -> 0.00010724063 | E12: 1.5 | F12: =((((4*D12)/(PI()*E12))^(0.5))*1000) -> 9.5408946 | G12: 12 | I12: 26 | J12: 160 | K12: =((10.675*((D12/J12))^(1.85))*C12)/(G12/1000)^(4.87) -> 0.25887163 | P12: F-G
B13: F-H | C13: 2.29 | D13: ='Caudal de Diseño'!J345 -> 0.00022364205 | E13: 1.5 | F13: =((((4*D13)/(PI()*E13))^(0.5))*1000) -> 13.777999 | G13: 18 | I13: 26 | J13: 160 | K13: =((10.675*((D13/J13))^(1.85))*C13)/(G13/1000)^(4.87) -> 0.11326043 | P13: E-H
B14: H-I | C14: 3.95 | D14: ='Caudal de Diseño'!J345 -> 0.00022364205 | E14: 1.5 | F14: =((((4*D14)/(PI()*E14))^(0.5))*1000) -> 13.777999 | G14: 18 | I14: 26 | J14: 160 | K14: =((10.675*((D14/J14))^(1.85))*C14)/(G14/1000)^(4.87) -> 0.19536187 | P14: H-I
B15: H-J | C15: 6.92 | D15: ='Caudal de Diseño'!J392 -> 0.00031475328 | E15: 1.5 | F15: =((((4*D15)/(PI()*E15))^(0.5))*1000) -> 16.345363 | G15: 18 | I15: 26 | J15: 160 | K15: =((10.675*((D15/J15))^(1.85))*C15)/(G15/1000)^(4.87) -> 0.64405048 | P15: H-J
B16: J-K | C16: 30.63 | D16: =D15 -> 0.00031475328 | E16: 1.5 | F16: =((((4*D16)/(PI()*E16))^(0.5))*1000) -> 16.345363 | G16: 18 | I16: 26 | J16: 160 | K16: =((10.675*((D16/J16))^(1.85))*C16)/(G16/1000)^(4.87) -> 2.850761 | P16: J-K
B17: K-L | C17: 3.92 | D17: ='Caudal de Diseño'!J416 -> 0.00010724063 | E17: 1.5 | F17: =((((4*D17)/(PI()*E17))^(0.5))*1000) -> 9.5408946 | G17: 12 | I17: 26 | J17: 160 | K17: =((10.675*((D17/J17))^(1.85))*C17)/(G17/1000)^(4.87) -> 0.35857837 | P17: K-L
B18: K-M | C18: 14.28 | D18: ='Caudal de Diseño'!J440 -> 0.00027110497 | E18: 1.5 | F18: =((((4*D18)/(PI()*E18))^(0.5))*1000) -> 15.169741 | G18: 18 | I18: 26 | J18: 160 | K18: =((10.675*((D18/J18))^(1.85))*C18)/(G18/1000)^(4.87) -> 1.0083269 | P18: M-N
B19: M-N | C19: 7.12 | D19: =D18 -> 0.00027110497 | E19: 1.5 | F19: =((((4*D19)/(PI()*E19))^(0.5))*1000) -> 15.169741 | G19: 18 | I19: 26 | J19: 160 | K19: =((10.675*((D19/J19))^(1.85))*C19)/(G19/1000)^(4.87) -> 0.50275122
B20: N-O | C20: 4.03 | D20: ='Caudal de Diseño'!J464 -> 0.00022364205 | E20: 1.5 | F20: =((((4*D20)/(PI()*E20))^(0.5))*1000) -> 13.777999 | G20: 18 | I20: 26 | J20: 160 | K20: =((10.675*((D20/J20))^(1.85))*C20)/(G20/1000)^(4.87) -> 0.19931857
B21: N-P | C21: 2.17 | D21: ='Caudal de Diseño'!J487 -> 0.00010724063 | E21: 1.5 | F21: =((((4*D21)/(PI()*E21))^(0.5))*1000) -> 9.5408946 | G21: 12 | I21: 26 | J21: 160 | K21: =((10.675*((D21/J21))^(1.85))*C21)/(G21/1000)^(4.87) -> 0.19849874
B22: P-Q | C22: 3.06 | D22: =D21 -> 0.00010724063 | E22: 1.5 | F22: =((((4*D22)/(PI()*E22))^(0.5))*1000) -> 9.5408946 | G22: 12 | I22: 26 | J22: 160 | K22: =((10.675*((D22/J22))^(1.85))*C22)/(G22/1000)^(4.87) -> 0.27991067 | L22: 2 | M22: 0.75 | O22: =M22+L22+K22+K21+K19+K18+K16+K15+K13+K11+K10+K9+K7 -> 9.756501 | Q22: No se requiere sistema de bombeo

Sheet Memoria de Cálculo
B3: TRAMO | C3: Longitud | D3: Caudal | E3: Velocidad | F3: Diam | G3: Diam | H3: Diam | I3: SDR | J3: C | K3: Caída | L3: Presión | M3: Altura | N3: Tramos | O3: Ruta | P3: TRAMO
C4: tubería | F4: inter | G4: selec | H4: nominal | K4: Presión | L4: mínima | M4: geométrica | N4: Críticos | O4: Crítica
C5: (m) | D5: (m3/s) | E5: (m/s) | F5: (mm) | G5: (mm) | H5: (pulg) | K5: (mca) | L5: (mca) | M5: (m) | O5: (mca)
B7: A-B | C7: 5.63 | D7: ='Caudal de Diseño'!H18 -> 0.0011717176 | E7: 1.5 | F7: =((((4*D7)/(PI()*E7))^(0.5))*1000) -> 31.537039 | G7: 38 | I7: 26 | J7: 160 | K7: =((10.675*((D7/J7))^(1.85))*C7)/(G7/1000)^(4.87) -> 0.15668618 | P7: A-B
B8: B-C | C8: 24.15 | D8: ='Caudal de Diseño'!H41 -> 0.00075980651 | E8: 1.5 | F8: =((((4*D8)/(PI()*E8))^(0.5))*1000) -> 25.395744 | G8: 31 | I8: 26 | J8: 160 | K8: =((10.675*((D8/J8))^(1.85))*C8)/(G8/1000)^(4.87) -> 0.81289072 | P8: B-C
B9: C-D | C9: 6.92 | D9: =D8 -> 0.00075980651 | E9: 1.5 | F9: =((((4*D9)/(PI()*E9))^(0.5))*1000) -> 25.395744 | G9: 31 | I9: 26 | J9: 160 | K9: =((10.675*((D9/J9))^(1.85))*C9)/(G9/1000)^(4.87) -> 0.23292769 | P9: C-D
B10: D-E | C10: 5.29 | D10: ='Caudal de Diseño'!H65 -> 0.00048922594 | E10: 1.5 | F10: =((((4*D10)/(PI()*E10))^(0.5))*1000) -> 20.378123 | G10: 25 | I10: 26 | J10: 160 | K10: =((10.675*((D10/J10))^(1.85))*C10)/(G10/1000)^(4.87) -> 0.22481552 | P10: D-E
B11: D-F | C11: 2.69 | D11: ='Caudal de Diseño'!H88 -> 0.00046638822 | E11: 1.5 | F11: =((((4*D11)/(PI()*E11))^(0.5))*1000) -> 19.896799 | G11: 25 | I11: 26 | J11: 160 | K11: =((10.675*((D11/J11))^(1.85))*C11)/(G11/1000)^(4.87) -> 0.10464377 | P11: E-F
B12: F-G | C12: 3.03 | D12: ='Caudal de Diseño'!H111 -> 0.00031475328 | E12: 1.5 | F12: =((((4*D12)/(PI()*E12))^(0.5))*1000) -> 16.345363 | G12: 18 | I12: 26 | J12: 160 | K12: =((10.675*((D12/J12))^(1.85))*C12)/(G12/1000)^(4.87) -> 0.28200476 | P12: F-G
B13: F-H | C13: 7.1 | D13: ='Caudal de Diseño'!H134 -> 0.00027110497 | E13: 1.5 | F13: =((((4*D13)/(PI()*E13))^(0.5))*1000) -> 15.169741 | G13: 18 | I13: 26 | J13: 160 | K13: =((10.675*((D13/J13))^(1.85))*C13)/(G13/1000)^(4.87) -> 0.501339 | P13: E-H
B14: H-I | C14: 21.78 | D14: =D13 -> 0.00027110497 | E14: 1.5 | F14: =((((4*D14)/(PI()*E14))^(0.5))*1000) -> 15.169741 | G14: 18 | I14: 26 | J14: 160 | K14: =((10.675*((D14/J14))^(1.85))*C14)/(G14/1000)^(4.87) -> 1.5379103 | P14: H-I
B15: I-J | C15: 7.28 | D15: =D14 -> 0.00027110497 | E15: 1.5 | F15: =((((4*D15)/(PI()*E15))^(0.5))*1000) -> 15.169741 | G15: 18 | I15: 26 | J15: 160 | K15: =((10.675*((D15/J15))^(1.85))*C15)/(G15/1000)^(4.87) -> 0.514049 | L15: 2 | M15: 0.75 | O15: =K15+K14+K13+K10+K9+K8+K7+M15+L15 -> 6.7306184 | P15: H-J | Q15: No se requiere sistema de bombeo
B16: B-K | C16: 7.88 | D16: ='Caudal de Diseño'!H157 -> 0.00071372296 | E16: 1.5 | F16: =((((4*D16)/(PI()*E16))^(0.5))*1000) -> 24.61355 | G16: 31 | I16: 26 | J16: 160 | K16: =((10.675*((D16/J16))^(1.85))*C16)/(G16/1000)^(4.87) -> 0.23624932 | P16: J-K
B17: K-P | C17: 4.12 | D17: ='Caudal de Diseño'!H181 -> 0.00031475328 | E17: 1.5 | F17: =((((4*D17)/(PI()*E17))^(0.5))*1000) -> 16.345363 | G17: 18 | I17: 26 | J17: 160 | K17: =((10.675*((D17/J17))^(1.85))*C17)/(G17/1000)^(4.87) -> 0.38345202 | P17: K-L
B18: K-L | C18: 14.28 | D18: ='Caudal de Diseño'!H204 -> 0.00056536848 | E18: 1.5 | F18: =((((4*D18)/(PI()*E18))^(0.5))*1000) -> 21.906612 | G18: 25 | I18: 26 | J18: 160 | K18: =((10.675*((D18/J18))^(1.85))*C18)/(G18/1000)^(4.87) -> 0.79308498 | P18: M-N
B19: L-M | C19: 7.12 | D19: =D18 -> 0.00056536848 | E19: 1.5 | F19: =((((4*D19)/(PI()*E19))^(0.5))*1000) -> 21.906612 | G19: 25 | I19: 26 | J19: 160 | K19: =((10.675*((D19/J19))^(1.85))*C19)/(G19/1000)^(4.87) -> 0.39543173
B20: M-Q | C20: 4.23 | D20: ='Caudal de Diseño'!H227 -> 0.00039421208 | E20: 1.5 | F20: =((((4*D20)/(PI()*E20))^(0.5))*1000) -> 18.292556 | G20: 25 | I20: 26 | J20: 160 | K20: =((10.675*((D20/J20))^(1.85))*C20)/(G20/1000)^(4.87) -> 0.12056432
B21: M-N | C21: 2.57 | D21: ='Caudal de Diseño'!H250 -> 0.00031475328 | E21: 1.5 | F21: =((((4*D21)/(PI()*E21))^(0.5))*1000) -> 16.345363 | G21: 18 | I21: 26 | J21: 160 | K21: =((10.675*((D21/J21))^(1.85))*C21)/(G21/1000)^(4.87) -> 0.23919216
B22: N-O | C22: 3.26 | D22: =D21 -> 0.00031475328 | E22: 1.5 | F22: =((((4*D22)/(PI()*E22))^(0.5))*1000) -> 16.345363 | G22: 18 | I22: 26 | J22: 160 | K22: =((10.675*((D22/J22))^(1.85))*C22)/(G22/1000)^(4.87) -> 0.30341107 | L22: 2 | M22: 0.75 | O22: =M22+L22+K22+K21+K19+K18+K16+K7 -> 4.8740554
